<?xml version="1.0"?>
<robot name="scara_robot">
    <!-- Base link -->
    <link name="base_link">
        <visual>
            <geometry>
                <cylinder length="0.1" radius="0.3" />
            </geometry>
            <origin rpy="0 0 0" xyz="0 0 0"/>
            <material name="green">
                <color rgba="0.5647 0.9333 0.5647 1" />
            </material>
        </visual>
    </link>

    <!-- Joint 1: Base to first_link -->
    <joint name="joint_1" type="revolute">
        <parent link="base_link" />
        <child link="first_link" />
        <origin rpy="0 0 0" xyz="0 0 0.05"/>
        <axis xyz="0 0 1" />
        <!-- How far this joint can rotate -->
        <limit effort="10" lower="-3.14" upper="3.14" velocity="1" />
    </joint>

    <!-- Shoulder link -->
    <link name="first_link">
        <visual>
            <geometry>
                <cylinder length="0.5" radius="0.08" />
            </geometry>
            <origin rpy="0 0 0" xyz="0 0 0.25"/>
            <material name="yellow">
                <color rgba="1 1 0 1" />
            </material>
        </visual>
    </link>

    <!-- Joint 2: Shoulder to Elbow -->
    <joint name="joint_2" type="prismatic">
        <parent link="first_link" />
        <child link="second_link" />
        <origin rpy="0 0 0" xyz="0 0 0.5"/>
        <axis xyz="0 1 0" />
        <!-- How far this joint can translate -->
        <limit effort="10" lower="-3.14" upper="3.14" velocity="1" />
    </joint>

    <!-- Elbow link -->
    <link name="second_link">
        <visual>
            <geometry>
                <box size= "0.2 0.7 0.1"/>
            </geometry>
            <origin rpy="0 0 0" xyz="0 0 0.05"/>
            <material name="red">
                <color rgba="0 0 1 1" />
            </material>
        </visual>
    </link>

</robot>
